{
 "cells": [
  {
   "cell_type": "markdown",
   "metadata": {},
   "source": [
    "# Deep Belief Networks"
   ]
  },
  {
   "cell_type": "code",
   "execution_count": 99,
   "metadata": {},
   "outputs": [
    {
     "name": "stdout",
     "output_type": "stream",
     "text": [
      "Epoch 1/5\n"
     ]
    },
    {
     "name": "stderr",
     "output_type": "stream",
     "text": [
      "2023-12-24 01:28:29.101592: W tensorflow/core/framework/op_kernel.cc:1827] UNKNOWN: JIT compilation failed.\n"
     ]
    },
    {
     "ename": "UnknownError",
     "evalue": "Graph execution error:\n\nDetected at node sequential_6/rbm_10/Sigmoid defined at (most recent call last):\n  File \"<frozen runpy>\", line 198, in _run_module_as_main\n\n  File \"<frozen runpy>\", line 88, in _run_code\n\n  File \"/home/kali/rep/uj/.venv/lib/python3.11/site-packages/ipykernel_launcher.py\", line 17, in <module>\n\n  File \"/home/kali/rep/uj/.venv/lib/python3.11/site-packages/traitlets/config/application.py\", line 1053, in launch_instance\n\n  File \"/home/kali/rep/uj/.venv/lib/python3.11/site-packages/ipykernel/kernelapp.py\", line 736, in start\n\n  File \"/home/kali/rep/uj/.venv/lib/python3.11/site-packages/tornado/platform/asyncio.py\", line 195, in start\n\n  File \"/usr/lib/python3.11/asyncio/base_events.py\", line 607, in run_forever\n\n  File \"/usr/lib/python3.11/asyncio/base_events.py\", line 1922, in _run_once\n\n  File \"/usr/lib/python3.11/asyncio/events.py\", line 80, in _run\n\n  File \"/home/kali/rep/uj/.venv/lib/python3.11/site-packages/ipykernel/kernelbase.py\", line 516, in dispatch_queue\n\n  File \"/home/kali/rep/uj/.venv/lib/python3.11/site-packages/ipykernel/kernelbase.py\", line 505, in process_one\n\n  File \"/home/kali/rep/uj/.venv/lib/python3.11/site-packages/ipykernel/kernelbase.py\", line 412, in dispatch_shell\n\n  File \"/home/kali/rep/uj/.venv/lib/python3.11/site-packages/ipykernel/kernelbase.py\", line 740, in execute_request\n\n  File \"/home/kali/rep/uj/.venv/lib/python3.11/site-packages/ipykernel/ipkernel.py\", line 422, in do_execute\n\n  File \"/home/kali/rep/uj/.venv/lib/python3.11/site-packages/ipykernel/zmqshell.py\", line 546, in run_cell\n\n  File \"/home/kali/rep/uj/.venv/lib/python3.11/site-packages/IPython/core/interactiveshell.py\", line 3024, in run_cell\n\n  File \"/home/kali/rep/uj/.venv/lib/python3.11/site-packages/IPython/core/interactiveshell.py\", line 3079, in _run_cell\n\n  File \"/home/kali/rep/uj/.venv/lib/python3.11/site-packages/IPython/core/async_helpers.py\", line 129, in _pseudo_sync_runner\n\n  File \"/home/kali/rep/uj/.venv/lib/python3.11/site-packages/IPython/core/interactiveshell.py\", line 3284, in run_cell_async\n\n  File \"/home/kali/rep/uj/.venv/lib/python3.11/site-packages/IPython/core/interactiveshell.py\", line 3466, in run_ast_nodes\n\n  File \"/home/kali/rep/uj/.venv/lib/python3.11/site-packages/IPython/core/interactiveshell.py\", line 3526, in run_code\n\n  File \"/tmp/ipykernel_8822/993550185.py\", line 41, in <module>\n\n  File \"/home/kali/rep/uj/.venv/lib/python3.11/site-packages/keras/src/utils/traceback_utils.py\", line 65, in error_handler\n\n  File \"/home/kali/rep/uj/.venv/lib/python3.11/site-packages/keras/src/engine/training.py\", line 1807, in fit\n\n  File \"/home/kali/rep/uj/.venv/lib/python3.11/site-packages/keras/src/engine/training.py\", line 1401, in train_function\n\n  File \"/home/kali/rep/uj/.venv/lib/python3.11/site-packages/keras/src/engine/training.py\", line 1384, in step_function\n\n  File \"/home/kali/rep/uj/.venv/lib/python3.11/site-packages/keras/src/engine/training.py\", line 1373, in run_step\n\n  File \"/home/kali/rep/uj/.venv/lib/python3.11/site-packages/keras/src/engine/training.py\", line 1150, in train_step\n\n  File \"/home/kali/rep/uj/.venv/lib/python3.11/site-packages/keras/src/utils/traceback_utils.py\", line 65, in error_handler\n\n  File \"/home/kali/rep/uj/.venv/lib/python3.11/site-packages/keras/src/engine/training.py\", line 590, in __call__\n\n  File \"/home/kali/rep/uj/.venv/lib/python3.11/site-packages/keras/src/utils/traceback_utils.py\", line 65, in error_handler\n\n  File \"/home/kali/rep/uj/.venv/lib/python3.11/site-packages/keras/src/engine/base_layer.py\", line 1149, in __call__\n\n  File \"/home/kali/rep/uj/.venv/lib/python3.11/site-packages/keras/src/utils/traceback_utils.py\", line 96, in error_handler\n\n  File \"/home/kali/rep/uj/.venv/lib/python3.11/site-packages/keras/src/engine/sequential.py\", line 398, in call\n\n  File \"/home/kali/rep/uj/.venv/lib/python3.11/site-packages/keras/src/engine/functional.py\", line 515, in call\n\n  File \"/home/kali/rep/uj/.venv/lib/python3.11/site-packages/keras/src/engine/functional.py\", line 672, in _run_internal_graph\n\n  File \"/home/kali/rep/uj/.venv/lib/python3.11/site-packages/keras/src/utils/traceback_utils.py\", line 65, in error_handler\n\n  File \"/home/kali/rep/uj/.venv/lib/python3.11/site-packages/keras/src/engine/base_layer.py\", line 1149, in __call__\n\n  File \"/home/kali/rep/uj/.venv/lib/python3.11/site-packages/keras/src/utils/traceback_utils.py\", line 96, in error_handler\n\n  File \"/tmp/ipykernel_8822/3008580642.py\", line 29, in call\n\nJIT compilation failed.\n\t [[{{node sequential_6/rbm_10/Sigmoid}}]] [Op:__inference_train_function_5115]",
     "output_type": "error",
     "traceback": [
      "\u001b[0;31m---------------------------------------------------------------------------\u001b[0m",
      "\u001b[0;31mUnknownError\u001b[0m                              Traceback (most recent call last)",
      "Cell \u001b[0;32mIn[99], line 41\u001b[0m\n\u001b[1;32m     39\u001b[0m \u001b[39m# Compile and train the model\u001b[39;00m\n\u001b[1;32m     40\u001b[0m model\u001b[39m.\u001b[39mcompile(optimizer\u001b[39m=\u001b[39m\u001b[39m'\u001b[39m\u001b[39madam\u001b[39m\u001b[39m'\u001b[39m, loss\u001b[39m=\u001b[39m\u001b[39m'\u001b[39m\u001b[39mmean_squared_error\u001b[39m\u001b[39m'\u001b[39m)\n\u001b[0;32m---> 41\u001b[0m model\u001b[39m.\u001b[39;49mfit(x_train, x_train, epochs\u001b[39m=\u001b[39;49m\u001b[39m5\u001b[39;49m)\n\u001b[1;32m     43\u001b[0m \u001b[39m# Visualize the weights of the first RBM layer\u001b[39;00m\n\u001b[1;32m     44\u001b[0m weights \u001b[39m=\u001b[39m model\u001b[39m.\u001b[39mlayers[\u001b[39m0\u001b[39m]\u001b[39m.\u001b[39mw\u001b[39m.\u001b[39mnumpy()\u001b[39m.\u001b[39mreshape(\u001b[39m784\u001b[39m, \u001b[39m256\u001b[39m)\n",
      "File \u001b[0;32m~/rep/uj/.venv/lib/python3.11/site-packages/keras/src/utils/traceback_utils.py:70\u001b[0m, in \u001b[0;36mfilter_traceback.<locals>.error_handler\u001b[0;34m(*args, **kwargs)\u001b[0m\n\u001b[1;32m     67\u001b[0m     filtered_tb \u001b[39m=\u001b[39m _process_traceback_frames(e\u001b[39m.\u001b[39m__traceback__)\n\u001b[1;32m     68\u001b[0m     \u001b[39m# To get the full stack trace, call:\u001b[39;00m\n\u001b[1;32m     69\u001b[0m     \u001b[39m# `tf.debugging.disable_traceback_filtering()`\u001b[39;00m\n\u001b[0;32m---> 70\u001b[0m     \u001b[39mraise\u001b[39;00m e\u001b[39m.\u001b[39mwith_traceback(filtered_tb) \u001b[39mfrom\u001b[39;00m \u001b[39mNone\u001b[39;00m\n\u001b[1;32m     71\u001b[0m \u001b[39mfinally\u001b[39;00m:\n\u001b[1;32m     72\u001b[0m     \u001b[39mdel\u001b[39;00m filtered_tb\n",
      "File \u001b[0;32m~/rep/uj/.venv/lib/python3.11/site-packages/tensorflow/python/eager/execute.py:53\u001b[0m, in \u001b[0;36mquick_execute\u001b[0;34m(op_name, num_outputs, inputs, attrs, ctx, name)\u001b[0m\n\u001b[1;32m     51\u001b[0m \u001b[39mtry\u001b[39;00m:\n\u001b[1;32m     52\u001b[0m   ctx\u001b[39m.\u001b[39mensure_initialized()\n\u001b[0;32m---> 53\u001b[0m   tensors \u001b[39m=\u001b[39m pywrap_tfe\u001b[39m.\u001b[39mTFE_Py_Execute(ctx\u001b[39m.\u001b[39m_handle, device_name, op_name,\n\u001b[1;32m     54\u001b[0m                                       inputs, attrs, num_outputs)\n\u001b[1;32m     55\u001b[0m \u001b[39mexcept\u001b[39;00m core\u001b[39m.\u001b[39m_NotOkStatusException \u001b[39mas\u001b[39;00m e:\n\u001b[1;32m     56\u001b[0m   \u001b[39mif\u001b[39;00m name \u001b[39mis\u001b[39;00m \u001b[39mnot\u001b[39;00m \u001b[39mNone\u001b[39;00m:\n",
      "\u001b[0;31mUnknownError\u001b[0m: Graph execution error:\n\nDetected at node sequential_6/rbm_10/Sigmoid defined at (most recent call last):\n  File \"<frozen runpy>\", line 198, in _run_module_as_main\n\n  File \"<frozen runpy>\", line 88, in _run_code\n\n  File \"/home/kali/rep/uj/.venv/lib/python3.11/site-packages/ipykernel_launcher.py\", line 17, in <module>\n\n  File \"/home/kali/rep/uj/.venv/lib/python3.11/site-packages/traitlets/config/application.py\", line 1053, in launch_instance\n\n  File \"/home/kali/rep/uj/.venv/lib/python3.11/site-packages/ipykernel/kernelapp.py\", line 736, in start\n\n  File \"/home/kali/rep/uj/.venv/lib/python3.11/site-packages/tornado/platform/asyncio.py\", line 195, in start\n\n  File \"/usr/lib/python3.11/asyncio/base_events.py\", line 607, in run_forever\n\n  File \"/usr/lib/python3.11/asyncio/base_events.py\", line 1922, in _run_once\n\n  File \"/usr/lib/python3.11/asyncio/events.py\", line 80, in _run\n\n  File \"/home/kali/rep/uj/.venv/lib/python3.11/site-packages/ipykernel/kernelbase.py\", line 516, in dispatch_queue\n\n  File \"/home/kali/rep/uj/.venv/lib/python3.11/site-packages/ipykernel/kernelbase.py\", line 505, in process_one\n\n  File \"/home/kali/rep/uj/.venv/lib/python3.11/site-packages/ipykernel/kernelbase.py\", line 412, in dispatch_shell\n\n  File \"/home/kali/rep/uj/.venv/lib/python3.11/site-packages/ipykernel/kernelbase.py\", line 740, in execute_request\n\n  File \"/home/kali/rep/uj/.venv/lib/python3.11/site-packages/ipykernel/ipkernel.py\", line 422, in do_execute\n\n  File \"/home/kali/rep/uj/.venv/lib/python3.11/site-packages/ipykernel/zmqshell.py\", line 546, in run_cell\n\n  File \"/home/kali/rep/uj/.venv/lib/python3.11/site-packages/IPython/core/interactiveshell.py\", line 3024, in run_cell\n\n  File \"/home/kali/rep/uj/.venv/lib/python3.11/site-packages/IPython/core/interactiveshell.py\", line 3079, in _run_cell\n\n  File \"/home/kali/rep/uj/.venv/lib/python3.11/site-packages/IPython/core/async_helpers.py\", line 129, in _pseudo_sync_runner\n\n  File \"/home/kali/rep/uj/.venv/lib/python3.11/site-packages/IPython/core/interactiveshell.py\", line 3284, in run_cell_async\n\n  File \"/home/kali/rep/uj/.venv/lib/python3.11/site-packages/IPython/core/interactiveshell.py\", line 3466, in run_ast_nodes\n\n  File \"/home/kali/rep/uj/.venv/lib/python3.11/site-packages/IPython/core/interactiveshell.py\", line 3526, in run_code\n\n  File \"/tmp/ipykernel_8822/993550185.py\", line 41, in <module>\n\n  File \"/home/kali/rep/uj/.venv/lib/python3.11/site-packages/keras/src/utils/traceback_utils.py\", line 65, in error_handler\n\n  File \"/home/kali/rep/uj/.venv/lib/python3.11/site-packages/keras/src/engine/training.py\", line 1807, in fit\n\n  File \"/home/kali/rep/uj/.venv/lib/python3.11/site-packages/keras/src/engine/training.py\", line 1401, in train_function\n\n  File \"/home/kali/rep/uj/.venv/lib/python3.11/site-packages/keras/src/engine/training.py\", line 1384, in step_function\n\n  File \"/home/kali/rep/uj/.venv/lib/python3.11/site-packages/keras/src/engine/training.py\", line 1373, in run_step\n\n  File \"/home/kali/rep/uj/.venv/lib/python3.11/site-packages/keras/src/engine/training.py\", line 1150, in train_step\n\n  File \"/home/kali/rep/uj/.venv/lib/python3.11/site-packages/keras/src/utils/traceback_utils.py\", line 65, in error_handler\n\n  File \"/home/kali/rep/uj/.venv/lib/python3.11/site-packages/keras/src/engine/training.py\", line 590, in __call__\n\n  File \"/home/kali/rep/uj/.venv/lib/python3.11/site-packages/keras/src/utils/traceback_utils.py\", line 65, in error_handler\n\n  File \"/home/kali/rep/uj/.venv/lib/python3.11/site-packages/keras/src/engine/base_layer.py\", line 1149, in __call__\n\n  File \"/home/kali/rep/uj/.venv/lib/python3.11/site-packages/keras/src/utils/traceback_utils.py\", line 96, in error_handler\n\n  File \"/home/kali/rep/uj/.venv/lib/python3.11/site-packages/keras/src/engine/sequential.py\", line 398, in call\n\n  File \"/home/kali/rep/uj/.venv/lib/python3.11/site-packages/keras/src/engine/functional.py\", line 515, in call\n\n  File \"/home/kali/rep/uj/.venv/lib/python3.11/site-packages/keras/src/engine/functional.py\", line 672, in _run_internal_graph\n\n  File \"/home/kali/rep/uj/.venv/lib/python3.11/site-packages/keras/src/utils/traceback_utils.py\", line 65, in error_handler\n\n  File \"/home/kali/rep/uj/.venv/lib/python3.11/site-packages/keras/src/engine/base_layer.py\", line 1149, in __call__\n\n  File \"/home/kali/rep/uj/.venv/lib/python3.11/site-packages/keras/src/utils/traceback_utils.py\", line 96, in error_handler\n\n  File \"/tmp/ipykernel_8822/3008580642.py\", line 29, in call\n\nJIT compilation failed.\n\t [[{{node sequential_6/rbm_10/Sigmoid}}]] [Op:__inference_train_function_5115]"
     ]
    }
   ],
   "source": [
    "import numpy as np\n",
    "import matplotlib.pyplot as plt\n",
    "import tensorflow as tf\n",
    "from keras.datasets import mnist\n",
    "from keras.layers import Dense, Layer\n",
    "from keras.models import Sequential\n",
    "\n",
    "# Load the MNIST dataset\n",
    "(x_train, _), (x_test, _) = mnist.load_data()\n",
    "x_train, x_test = x_train / 255.0, x_test / 255.0\n",
    "x_train = x_train.reshape(-1, 784)\n",
    "x_test = x_test.reshape(-1, 784)\n",
    "\n",
    "# Define the RBM layer\n",
    "class RBM(Layer):\n",
    "    def __init__(self, units):\n",
    "        super(RBM, self).__init__()\n",
    "        self.units = units\n",
    "\n",
    "    def build(self, input_shape):\n",
    "        self.w = self.add_weight(shape=(input_shape[-1], self.units),\n",
    "                                 initializer='random_normal',\n",
    "                                 trainable=True)\n",
    "        self.b = self.add_weight(shape=(self.units,),\n",
    "                                 initializer='zeros',\n",
    "                                 trainable=True)\n",
    "\n",
    "    def call(self, inputs):\n",
    "        h = tf.nn.sigmoid(tf.matmul(inputs, self.w) + self.b)\n",
    "        return h\n",
    "\n",
    "# Create the DBN Model\n",
    "model = Sequential([\n",
    "    RBM(256),  # First RBM layer\n",
    "    RBM(64),    # Second RBM layer\n",
    "    Dense(784, activation='sigmoid')  # Adding a dense layer to map back to original dimension\n",
    "])\n",
    "\n",
    "# Compile and train the model\n",
    "model.compile(optimizer='adam', loss='mean_squared_error')\n",
    "model.fit(x_train, x_train, epochs=5)\n",
    "\n",
    "# Visualize the weights of the first RBM layer\n",
    "weights = model.layers[0].w.numpy().reshape(784, 256)\n",
    "\n",
    "fig, axes = plt.subplots(16, 16, figsize=(10, 10))\n",
    "for i, ax in enumerate(axes.flat):\n",
    "    if i < 256:\n",
    "        ax.imshow(weights[:, i].reshape(28, 28), cmap='gray')\n",
    "        ax.axis('off')\n",
    "\n",
    "plt.suptitle(\"Visualization of the First RBM Layer Weights in the DBN\", fontsize=16)\n",
    "plt.show()\n"
   ]
  }
 ],
 "metadata": {
  "kernelspec": {
   "display_name": ".venv",
   "language": "python",
   "name": "python3"
  },
  "language_info": {
   "codemirror_mode": {
    "name": "ipython",
    "version": 3
   },
   "file_extension": ".py",
   "mimetype": "text/x-python",
   "name": "python",
   "nbconvert_exporter": "python",
   "pygments_lexer": "ipython3",
   "version": "3.11.6"
  },
  "orig_nbformat": 4
 },
 "nbformat": 4,
 "nbformat_minor": 2
}
